#include <iostream>
#include <stdexcept>
using namespace std;

int main() {
    int a = 10, b = 0, c;
    try {
        if (b == 0) {
            throw runtime_error("divide by zero is an error");
            c = a / b;
        }
    }
    catch (const runtime_error &error) {
        cout << "exception occurred: " << error.what() << endl;
    }
    catch (...) {
        cout << "some exception occurred" << endl;
    }

    return 0;
}
